# agent
This is the error which I am encountering and not being able to resolve .
agents.py,tools.py,tasks.py,crew.py except these files all the other files were present in .venv/lib/site-packages
Can you please help me out with this?


Traceback (most recent call last):
  File "C:\Users\l43ar\Downloads\business\crew.py", line 1, in <module>
    from crewai import Crew,Process
  File "C:\Users\l43ar\Downloads\business\.venv\Lib\site-packages\crewai\__init__.py", line 3, in <module>
    from crewai.agent import Agent
  File "C:\Users\l43ar\Downloads\business\.venv\Lib\site-packages\crewai\agent.py", line 9, in <module>
    from crewai.agents.agent_builder.base_agent import BaseAgent
  File "C:\Users\l43ar\Downloads\business\.venv\Lib\site-packages\crewai\agents\agent_builder\base_agent.py", line 1, in <module>
    class BaseAgent(ABC, BaseModel):
                    ^^^
NameError: name 'ABC' is not defined

(.venv) C:\Users\l43ar\Downloads\business>python crew.py
C:\Users\l43ar\Downloads\business\.venv\Lib\site-packages\pydantic\_internal\_config.py:345: UserWarning: Valid config keys have changed in V2:
* 'fields' has been removed
  warnings.warn(message, UserWarning)
Inserting batches in chromadb:   0%|                                                                                                                       | 0/1 [00:04<?, ?it/s]
Traceback (most recent call last):
  File "C:\Users\l43ar\Downloads\business\crew.py", line 3, in <module>
    from tasks import marketing,technical,business_planning
  File "C:\Users\l43ar\Downloads\business\tasks.py", line 5, in <module>
    marketing = Task(
                ^^^^^
  File "C:\Users\l43ar\Downloads\business\.venv\Lib\site-packages\pydantic\main.py", line 214, in __init__
    validated_self = self.__pydantic_validator__.validate_python(data, self_instance=self)
                     ^^^^^^^^^^^^^^^^^^^^^^^^^^^^^^^^^^^^^^^^^^^^^^^^^^^^^^^^^^^^^^^^^^^^^
  File "C:\Users\l43ar\Downloads\business\.venv\Lib\site-packages\crewai\agents\agent_builder\base_agent.py", line 137, in process_model_config
    return process_config(values, cls)
           ^^^^^^^^^^^^^^^^^^^^^^^^^^^
  File "C:\Users\l43ar\Downloads\business\.venv\Lib\site-packages\crewai\utilities\config.py", line 19, in process_config
    config = values.get("config", {})
             ^^^^^^^^^^
AttributeError: 'list' object has no attribute 'get'
